<?xml version="1.0" ?>
<!-- =================================================================================== -->
<!-- |    This document was autogenerated by xacro from inmoov.urdf.xacro              | -->
<!-- |    EDITING THIS FILE BY HAND IS NOT RECOMMENDED                                 | -->
<!-- =================================================================================== -->
<robot name="tomato" xmlns:xacro="http://ros.org/wiki/xacro">
  <link name="tomato">
    <inertial>
      <origin rpy="0 0 0" xyz="0 0 0.0"/>
      <mass value="0.5"/>
      <inertia ixx="0.05" ixy="0" ixz="0" iyy="0.06" iyz="0" izz="0.03"/>
    </inertial>
    <visual>
      <geometry>
        <mesh filename="tomato/10208_TomatoBeefSteak_v1.obj" scale="0.01 0.01 0.01"/>
      </geometry>
      <origin rpy="0 0 0" xyz="0 0 0.0"/>
      <material name="cbase">
        <color rgba="1 1 1 1"/>
      </material>
    </visual>
    <collision>
      <origin rpy="0 0 0" xyz="0 0 0"/>
      <geometry>
        <mesh filename="tomato/10208_TomatoBeefSteak_v1.obj" scale="0.01 0.01 0.01"/>
      </geometry>
    </collision>
  </link>
  <link name="plant">
    <inertial>
      <origin rpy="0 0 0" xyz="0 0 0.0"/>
      <mass value="0.0"/>
      <inertia ixx="0.05" ixy="0" ixz="0" iyy="0.06" iyz="0" izz="0.03"/>
    </inertial>
    <visual>
      <geometry>
        <mesh filename="tomato/VG18_1.obj" scale="2 2 2"/>
      </geometry>
      <origin rpy="1.57 0 0." xyz="0 0 0.0"/>
      <material name="cbase">
        <color rgba="1 1 1 1"/>
      </material>
    </visual>
  </link>
  <joint name="tomato_joint" type="revolute">
    <axis xyz="0 0 1"/>
    <limit effort="1000.0" lower="0.0" upper="0.548" velocity="0.5"/>
    <origin rpy="0 0 0" xyz="0.5 -0.3 0.45"/>
    <parent link="plant"/>
    <child link="tomato"/>
  </joint>

  <link name="tomato2">
    <inertial>
      <origin rpy="0 0 0" xyz="0 0 0.0"/>
      <mass value="0.5"/>
      <inertia ixx="0.03" ixy="0" ixz="0" iyy="0.00" iyz="0" izz="0.03"/>
    </inertial>
    <visual>
      <geometry>
        <mesh filename="tomato/10208_TomatoBeefSteak_v1.obj" scale="0.006 0.006 0.006"/>
      </geometry>
      <origin rpy="0.5 0 0" xyz="0 0 0.0"/>
      <material name="cbase">
        <color rgba="1 1 1 1"/>
      </material>
    </visual>
    <collision>
      <origin rpy="0.5 0 0" xyz="0 0 0"/>
      <geometry>
        <mesh filename="tomato/10208_TomatoBeefSteak_v1.obj" scale="0.006 0.006 0.006"/>
      </geometry>
    </collision>
  </link>
  <joint name="tomato_2" type="revolute">
    <axis xyz="0 0 1"/>
    <limit effort="1000.0" lower="0.0" upper="0.548" velocity="0.5"/>
    <origin rpy="0 0 0" xyz="0.1 0.20 0.85"/>
    <parent link="plant"/>
    <child link="tomato2"/>
  </joint>
  <link name="tomato3">
    <inertial>
      <origin rpy="0 0 0" xyz="0 0 0.0"/>
      <mass value="0.5"/>
      <inertia ixx="0.03" ixy="0" ixz="0" iyy="0.00" iyz="0" izz="0.03"/>
    </inertial>
    <visual>
      <geometry>
        <mesh filename="tomato/10208_TomatoBeefSteak_v1.obj" scale="0.008 0.008 0.008"/>
      </geometry>
      <origin rpy="0.5 0. 1." xyz="0 0 0.0"/>
      <material name="cbase">
        <color rgba="1 1 1 1"/>
      </material>
    </visual>
    <collision>
      <origin rpy="0.5 0. 1." xyz="0 0 0"/>
      <geometry>
        <mesh filename="tomato/10208_TomatoBeefSteak_v1.obj" scale="0.008 0.008 0.008"/>
      </geometry>
    </collision>
  </link>
  <joint name="tomato_3" type="revolute">
    <axis xyz="0 0 1"/>
    <limit effort="1000.0" lower="0.0" upper="0.548" velocity="0.5"/>
    <origin rpy="0 0 0" xyz="0.05 0.15 0.8"/>
    <parent link="plant"/>
    <child link="tomato3"/>
  </joint>
  <link name="tomato4">
    <inertial>
      <origin rpy="0 0 0" xyz="0 0 0.0"/>
      <mass value="0.5"/>
      <inertia ixx="0.03" ixy="0" ixz="0" iyy="0.00" iyz="0" izz="0.03"/>
    </inertial>
    <visual>
      <geometry>
        <mesh filename="tomato/10208_TomatoBeefSteak_v1.obj" scale="0.005 0.005 0.005"/>
      </geometry>
      <origin rpy="-0.5 0. -1." xyz="0 0 0.0"/>
      <material name="cbase">
        <color rgba="1 1 1 1"/>
      </material>
    </visual>
    <collision>
      <origin rpy="-0.5 0. -1." xyz="0 0 0"/>
      <geometry>
        <mesh filename="tomato/10208_TomatoBeefSteak_v1.obj" scale="0.005 0.005 0.005"/>
      </geometry>
    </collision>
  </link>
  <joint name="tomato_4" type="revolute">
    <axis xyz="0 0 1"/>
    <limit effort="1000.0" lower="0.0" upper="0.548" velocity="0.5"/>
    <origin rpy="0 0 0" xyz="-0.20 -0.05 0.95"/>
    <parent link="plant"/>
    <child link="tomato4"/>
  </joint>


</robot>
