<?xml version="1.0"?>
<robot name ="jakaUr">

 <material name="blue">
    <color rgba="0 0 0.8 1"/>
  </material>

  <material name="black">
    <color rgba="0 0 0 1"/>
  </material>

  <material name="white">
    <color rgba="1 1 1 1"/>
  </material>

  <link name="base_link">
    <inertial>
      <origin rpy="0 0 0" xyz="0 0 0.055"/>
      <mass value="0.0"/>
      <inertia ixx="0.05" ixy="0" ixz="0" iyy="0.06" iyz="0" izz="0.03"/>
    </inertial>

    <visual>
      <origin rpy="0 1.57079632 0" xyz="0 0 0"/>
      <geometry>
        <mesh filename="mesh/p1.dae"/>
      </geometry>
    </visual>

    <collision>
      <geometry>
         <mesh filename="mesh/p1.dae"/>
     </geometry>
      <origin rpy="0 1.57079632 0" xyz="0 0 0"/>
    </collision>
  </link>

  <link name="link_1">
    <visual>
      <geometry>
         <mesh filename="mesh/p2.dae"/>
      </geometry>
      <origin rpy=" 1.57079632  0  -1.57079632" xyz="0 0 0"/>
    </visual>

    <collision>
      <geometry>
         <mesh filename="mesh/p2.dae"/>
      </geometry>
      <origin rpy="1.57079632 0 -1.57079632" xyz="0 0 0"/>
  </collision>

  </link>



  <joint name="joint_1" type="revolute">
   <axis xyz="0 0 1"/>
    <limit effort="1000" lower="-3.14" upper="3.14" velocity="0.5"/>
    <origin rpy="0 0 0" xyz="0 0 0.094"/>
    <parent link="base_link"/>
    <child link="link_1"/>
  </joint>

  <link name="link_2">
    <visual>
      <geometry>
         <mesh filename="mesh/p3.dae"/>
      </geometry>
      <origin rpy="1.57079632 -1.57079632 2.61799387799" xyz="0 0 0"/>
   </visual>

    <collision>
   <geometry>
         <mesh filename="mesh/p3.dae"/>
      </geometry>
      <origin rpy="1.57079632 -1.57079632 2.61799387799 " xyz="0 0 0"/>
  </collision>

  </link>



  <joint name="joint_2" type="revolute">
   <axis xyz="0 0 1"/>
    <limit effort="1000" lower="-1.58" upper="3.58" velocity="0.5"/>
    <origin rpy="1.57079632 0 0" xyz="0 0 0"/>
    <parent link="link_1"/>
    <child link="link_2"/>
  </joint>


  <link name="link_3">
    <visual>
      <geometry>
         <mesh filename="mesh/p4.dae"/>
      </geometry>
      <origin rpy="0 0 -1.57079632" xyz="0 0 0.0135"/>
   </visual>
     <collision>
    <geometry>
         <mesh filename="mesh/p4.dae"/>
      </geometry>
      <origin rpy="0 0 -1.57079632" xyz="0 0 0.0135"/>
   </collision>

  </link>


  <joint name="joint_3" type="revolute">
   <axis xyz="0 0 1"/>
    <limit effort="1000" lower="-1.58" upper="3.58" velocity="0.5"/>
    <origin rpy="0 0 0" xyz="0.353 0 0"/>
    <parent link="link_2"/>
    <child link="link_3"/>
  </joint>

  <link name="link_4">
    <visual>
      <geometry>
         <mesh filename="mesh/p5.dae"/>
      </geometry>
      <origin rpy="-1.57079632 0 1.57079632" xyz="0 0 0"/>
   </visual>
    <collision>
  <geometry>
         <mesh filename="mesh/p5.dae"/>
      </geometry>
      <origin rpy="-1.57079632 0 1.57079632" xyz="0 0 0"/>
    </collision>

  </link>


  <joint name="joint_4" type="revolute">
   <axis xyz="0 0 1"/>
    <limit effort="1000" lower="-1.58" upper="3.58" velocity="0.5"/>
    <origin rpy="0 0 0" xyz="0.31 0 0.109"/>
    <parent link="link_3"/>
    <child link="link_4"/>
  </joint>

  <link name="link_5">
    <visual>
      <geometry>
         <mesh filename="mesh/p6.dae"/>
      </geometry>
      <origin rpy="3.14159265358 0 -1.57079632" xyz="0 0 0"/>
   </visual>

    <collision>
     <geometry>
         <mesh filename="mesh/p6.dae"/>
      </geometry>
      <origin rpy="3.14159265358 0 -1.57079632" xyz="0 0 0"/>
  </collision>

  </link>


  <joint name="joint_5" type="revolute">
   <axis xyz="0 0 1"/>
    <limit effort="1000" lower="-1.58" upper="3.58" velocity="0.5"/>
    <origin rpy="1.57079632 0 0" xyz="0 -0.0955 0"/>
    <parent link="link_4"/>
    <child link="link_5"/>
  </joint>


  <link name="link_6">
    <visual>
      <geometry>
         <mesh filename="mesh/p7.dae"/>
      </geometry>
      <origin rpy="-3.14159265358 0 0" xyz="0 0 0.03"/>
   </visual>

       <collision>
      <geometry>
         <mesh filename="mesh/p7.dae"/>
      </geometry>
      <origin rpy="-3.14159265358 0 0" xyz="0 0 0.03"/>
       </collision>

  </link>


  <joint name="joint_6" type="revolute">
   <axis xyz="0 0 1"/>
    <limit effort="1000" lower="-1.58" upper="3.58" velocity="0.5"/>
    <origin rpy="1.57079632 0 0" xyz="0 0.085 0"/>
    <parent link="link_5"/>
    <child link="link_6"/>
  </joint>

</robot>
